Workbook

Sheet 월별조회
A1: 월별 납품 내역서
A3: 매장명 | B3: 까미노 | D3: 조회월 | E3: 2026-06
A6: 총 납품 건수: | B6: =COUNTIFS(납품대장!C:C,B3,납품대장!B:B,">="&DATE(LEFT(E3,4),MID(E3,6,2),1),납품대장!B:B,"<"&DATE(LEFT(E3,4),MID(E3,6,2)+1,1),납품대장!G:G,">0") | C6: 건 | D6: 총 금액: | E6: =SUMIFS(납품대장!G:G,납품대장!C:C,B3,납품대장!B:B,">="&DATE(LEFT(E3,4),MID(E3,6,2),1),납품대장!B:B,"<"&DATE(LEFT(E3,4),MID(E3,6,2)+1,1),납품대장!G:G,">0")
A8: No | B8: 납품일 | C8: 작물명 | D8: 수량(g) | E8: 단가 | F8: 금액
A9: =IF(ROWS($A$9:A9)<=COUNTIFS(납품대장!$C:$C,$B$3,납품대장!$B:$B,">="&DATE(LEFT($E$3,4),MID($E$3,6,2),1),납품대장!$B:$B,"<"&DATE(LEFT($E$3,4),MID($E$3,6,2)+1,1),납품대장!$G:$G,">0"),ROWS($A$9:A9),"") | B9: {=IFERROR(INDEX(납품대장!$H$2:$H$225,SMALL(IF((납품대장!$C$2:$C$225=$B$3)*(MONTH(납품대장!$B$2:$B$225)=MID($E$3,6,2)*1)*(YEAR(납품대장!$B$2:$B$225)=LEFT($E$3,4)*1)*(납품대장!$G$2:$G$225>0),ROW(납품대장!$H$2:$H$225)-1),ROWS($B$9:B9))),"")} | C9: {=IFERROR(INDEX(납품대장!$D$2:$D$225,SMALL(IF((납품대장!$C$2:$C$225=$B$3)*(MONTH(납품대장!$B$2:$B$225)=MID($E$3,6,2)*1)*(YEAR(납품대장!$B$2:$B$225)=LEFT($E$3,4)*1)*(납품대장!$G$2:$G$225>0),ROW(납품대장!$D$2:$D$225)-1),ROWS($C$9:C9))),"")} | D9: {=IFERROR(INDEX(납품대장!$F$2:$F$225,SMALL(IF((납품대장!$C$2:$C$225=$B$3)*(MONTH(납품대장!$B$2:$B$225)=MID($E$3,6,2)*1)*(YEAR(납품대장!$B$2:$B$225)=LEFT($E$3,4)*1)*(납품대장!$G$2:$G$225>0),ROW(납품대장!$F$2:$F$225)-1),ROWS($D$9:D9))),"")} | E9: {=IFERROR(INDEX(납품대장!$E$2:$E$225,SMALL(IF((납품대장!$C$2:$C$225=$B$3)*(MONTH(납품대장!$B$2:$B$225)=MID($E$3,6,2)*1)*(YEAR(납품대장!$B$2:$B$225)=LEFT($E$3,4)*1)*(납품대장!$G$2:$G$225>0),ROW(납품대장!$E$2:$E$225)-1),ROWS($E$9:E9))),"")} | F9: {=IFERROR(INDEX(납품대장!$G$2:$G$225,SMALL(IF((납품대장!$C$2:$C$225=$B$3)*(MONTH(납품대장!$B$2:$B$225)=MID($E$3,6,2)*1)*(YEAR(납품대장!$B$2:$B$225)=LEFT($E$3,4)*1)*(납품대장!$G$2:$G$225>0),ROW(납품대장!$G$2:$G$225)-1),ROWS($F$9:F9))),"")}
A10: =IF(ROWS($A$9:A10)<=COUNTIFS(납품대장!$C:$C,$B$3,납품대장!$B:$B,">="&DATE(LEFT($E$3,4),MID($E$3,6,2),1),납품대장!$B:$B,"<"&DATE(LEFT($E$3,4),MID($E$3,6,2)+1,1),납품대장!$G:$G,">0"),ROWS($A$9:A10),"") | B10: {=IFERROR(INDEX(납품대장!$H$2:$H$225,SMALL(IF((납품대장!$C$2:$C$225=$B$3)*(MONTH(납품대장!$B$2:$B$225)=MID($E$3,6,2)*1)*(YEAR(납품대장!$B$2:$B$225)=LEFT($E$3,4)*1)*(납품대장!$G$2:$G$225>0),ROW(납품대장!$H$2:$H$225)-1),ROWS($B$9:B10))),"")} | C10: {=IFERROR(INDEX(납품대장!$D$2:$D$225,SMALL(IF((납품대장!$C$2:$C$225=$B$3)*(MONTH(납품대장!$B$2:$B$225)=MID($E$3,6,2)*1)*(YEAR(납품대장!$B$2:$B$225)=LEFT($E$3,4)*1)*(납품대장!$G$2:$G$225>0),ROW(납품대장!$D$2:$D$225)-1),ROWS($C$9:C10))),"")} | D10: {=IFERROR(INDEX(납품대장!$F$2:$F$225,SMALL(IF((납품대장!$C$2:$C$225=$B$3)*(MONTH(납품대장!$B$2:$B$225)=MID($E$3,6,2)*1)*(YEAR(납품대장!$B$2:$B$225)=LEFT($E$3,4)*1)*(납품대장!$G$2:$G$225>0),ROW(납품대장!$F$2:$F$225)-1),ROWS($D$9:D10))),"")} | E10: {=IFERROR(INDEX(납품대장!$E$2:$E$225,SMALL(IF((납품대장!$C$2:$C$225=$B$3)*(MONTH(납품대장!$B$2:$B$225)=MID($E$3,6,2)*1)*(YEAR(납품대장!$B$2:$B$225)=LEFT($E$3,4)*1)*(납품대장!$G$2:$G$225>0),ROW(납품대장!$E$2:$E$225)-1),ROWS($E$9:E10))),"")} | F10: {=IFERROR(INDEX(납품대장!$G$2:$G$225,SMALL(IF((납품대장!$C$2:$C$225=$B$3)*(MONTH(납품대장!$B$2:$B$225)=MID($E$3,6,2)*1)*(YEAR(납품대장!$B$2:$B$225)=LEFT($E$3,4)*1)*(납품대장!$G$2:$G$225>0),ROW(납품대장!$G$2:$G$225)-1),ROWS($F$9:F10))),"")}
A11: =IF(ROWS($A$9:A11)<=COUNTIFS(납품대장!$C:$C,$B$3,납품대장!$B:$B,">="&DATE(LEFT($E$3,4),MID($E$3,6,2),1),납품대장!$B:$B,"<"&DATE(LEFT($E$3,4),MID($E$3,6,2)+1,1),납품대장!$G:$G,">0"),ROWS($A$9:A11),"") | B11: {=IFERROR(INDEX(납품대장!$H$2:$H$225,SMALL(IF((납품대장!$C$2:$C$225=$B$3)*(MONTH(납품대장!$B$2:$B$225)=MID($E$3,6,2)*1)*(YEAR(납품대장!$B$2:$B$225)=LEFT($E$3,4)*1)*(납품대장!$G$2:$G$225>0),ROW(납품대장!$H$2:$H$225)-1),ROWS($B$9:B11))),"")} | C11: {=IFERROR(INDEX(납품대장!$D$2:$D$225,SMALL(IF((납품대장!$C$2:$C$225=$B$3)*(MONTH(납품대장!$B$2:$B$225)=MID($E$3,6,2)*1)*(YEAR(납품대장!$B$2:$B$225)=LEFT($E$3,4)*1)*(납품대장!$G$2:$G$225>0),ROW(납품대장!$D$2:$D$225)-1),ROWS($C$9:C11))),"")} | D11: {=IFERROR(INDEX(납품대장!$F$2:$F$225,SMALL(IF((납품대장!$C$2:$C$225=$B$3)*(MONTH(납품대장!$B$2:$B$225)=MID($E$3,6,2)*1)*(YEAR(납품대장!$B$2:$B$225)=LEFT($E$3,4)*1)*(납품대장!$G$2:$G$225>0),ROW(납품대장!$F$2:$F$225)-1),ROWS($D$9:D11))),"")} | E11: {=IFERROR(INDEX(납품대장!$E$2:$E$225,SMALL(IF((납품대장!$C$2:$C$225=$B$3)*(MONTH(납품대장!$B$2:$B$225)=MID($E$3,6,2)*1)*(YEAR(납품대장!$B$2:$B$225)=LEFT($E$3,4)*1)*(납품대장!$G$2:$G$225>0),ROW(납품대장!$E$2:$E$225)-1),ROWS($E$9:E11))),"")} | F11: {=IFERROR(INDEX(납품대장!$G$2:$G$225,SMALL(IF((납품대장!$C$2:$C$225=$B$3)*(MONTH(납품대장!$B$2:$B$225)=MID($E$3,6,2)*1)*(YEAR(납품대장!$B$2:$B$225)=LEFT($E$3,4)*1)*(납품대장!$G$2:$G$225>0),ROW(납품대장!$G$2:$G$225)-1),ROWS($F$9:F11))),"")}
A12: =IF(ROWS($A$9:A12)<=COUNTIFS(납품대장!$C:$C,$B$3,납품대장!$B:$B,">="&DATE(LEFT($E$3,4),MID($E$3,6,2),1),납품대장!$B:$B,"<"&DATE(LEFT($E$3,4),MID($E$3,6,2)+1,1),납품대장!$G:$G,">0"),ROWS($A$9:A12),"") | B12: {=IFERROR(INDEX(납품대장!$H$2:$H$225,SMALL(IF((납품대장!$C$2:$C$225=$B$3)*(MONTH(납품대장!$B$2:$B$225)=MID($E$3,6,2)*1)*(YEAR(납품대장!$B$2:$B$225)=LEFT($E$3,4)*1)*(납품대장!$G$2:$G$225>0),ROW(납품대장!$H$2:$H$225)-1),ROWS($B$9:B12))),"")} | C12: {=IFERROR(INDEX(납품대장!$D$2:$D$225,SMALL(IF((납품대장!$C$2:$C$225=$B$3)*(MONTH(납품대장!$B$2:$B$225)=MID($E$3,6,2)*1)*(YEAR(납품대장!$B$2:$B$225)=LEFT($E$3,4)*1)*(납품대장!$G$2:$G$225>0),ROW(납품대장!$D$2:$D$225)-1),ROWS($C$9:C12))),"")} | D12: {=IFERROR(INDEX(납품대장!$F$2:$F$225,SMALL(IF((납품대장!$C$2:$C$225=$B$3)*(MONTH(납품대장!$B$2:$B$225)=MID($E$3,6,2)*1)*(YEAR(납품대장!$B$2:$B$225)=LEFT($E$3,4)*1)*(납품대장!$G$2:$G$225>0),ROW(납품대장!$F$2:$F$225)-1),ROWS($D$9:D12))),"")} | E12: {=IFERROR(INDEX(납품대장!$E$2:$E$225,SMALL(IF((납품대장!$C$2:$C$225=$B$3)*(MONTH(납품대장!$B$2:$B$225)=MID($E$3,6,2)*1)*(YEAR(납품대장!$B$2:$B$225)=LEFT($E$3,4)*1)*(납품대장!$G$2:$G$225>0),ROW(납품대장!$E$2:$E$225)-1),ROWS($E$9:E12))),"")} | F12: {=IFERROR(INDEX(납품대장!$G$2:$G$225,SMALL(IF((납품대장!$C$2:$C$225=$B$3)*(MONTH(납품대장!$B$2:$B$225)=MID($E$3,6,2)*1)*(YEAR(납품대장!$B$2:$B$225)=LEFT($E$3,4)*1)*(납품대장!$G$2:$G$225>0),ROW(납품대장!$G$2:$G$225)-1),ROWS($F$9:F12))),"")}
A13: =IF(ROWS($A$9:A13)<=COUNTIFS(납품대장!$C:$C,$B$3,납품대장!$B:$B,">="&DATE(LEFT($E$3,4),MID($E$3,6,2),1),납품대장!$B:$B,"<"&DATE(LEFT($E$3,4),MID($E$3,6,2)+1,1),납품대장!$G:$G,">0"),ROWS($A$9:A13),"") | B13: {=IFERROR(INDEX(납품대장!$H$2:$H$225,SMALL(IF((납품대장!$C$2:$C$225=$B$3)*(MONTH(납품대장!$B$2:$B$225)=MID($E$3,6,2)*1)*(YEAR(납품대장!$B$2:$B$225)=LEFT($E$3,4)*1)*(납품대장!$G$2:$G$225>0),ROW(납품대장!$H$2:$H$225)-1),ROWS($B$9:B13))),"")} | C13: {=IFERROR(INDEX(납품대장!$D$2:$D$225,SMALL(IF((납품대장!$C$2:$C$225=$B$3)*(MONTH(납품대장!$B$2:$B$225)=MID($E$3,6,2)*1)*(YEAR(납품대장!$B$2:$B$225)=LEFT($E$3,4)*1)*(납품대장!$G$2:$G$225>0),ROW(납품대장!$D$2:$D$225)-1),ROWS($C$9:C13))),"")} | D13: {=IFERROR(INDEX(납품대장!$F$2:$F$225,SMALL(IF((납품대장!$C$2:$C$225=$B$3)*(MONTH(납품대장!$B$2:$B$225)=MID($E$3,6,2)*1)*(YEAR(납품대장!$B$2:$B$225)=LEFT($E$3,4)*1)*(납품대장!$G$2:$G$225>0),ROW(납품대장!$F$2:$F$225)-1),ROWS($D$9:D13))),"")} | E13: {=IFERROR(INDEX(납품대장!$E$2:$E$225,SMALL(IF((납품대장!$C$2:$C$225=$B$3)*(MONTH(납품대장!$B$2:$B$225)=MID($E$3,6,2)*1)*(YEAR(납품대장!$B$2:$B$225)=LEFT($E$3,4)*1)*(납품대장!$G$2:$G$225>0),ROW(납품대장!$E$2:$E$225)-1),ROWS($E$9:E13))),"")} | F13: {=IFERROR(INDEX(납품대장!$G$2:$G$225,SMALL(IF((납품대장!$C$2:$C$225=$B$3)*(MONTH(납품대장!$B$2:$B$225)=MID($E$3,6,2)*1)*(YEAR(납품대장!$B$2:$B$225)=LEFT($E$3,4)*1)*(납품대장!$G$2:$G$225>0),ROW(납품대장!$G$2:$G$225)-1),ROWS($F$9:F13))),"")}
A14: =IF(ROWS($A$9:A14)<=COUNTIFS(납품대장!$C:$C,$B$3,납품대장!$B:$B,">="&DATE(LEFT($E$3,4),MID($E$3,6,2),1),납품대장!$B:$B,"<"&DATE(LEFT($E$3,4),MID($E$3,6,2)+1,1),납품대장!$G:$G,">0"),ROWS($A$9:A14),"") | B14: {=IFERROR(INDEX(납품대장!$H$2:$H$225,SMALL(IF((납품대장!$C$2:$C$225=$B$3)*(MONTH(납품대장!$B$2:$B$225)=MID($E$3,6,2)*1)*(YEAR(납품대장!$B$2:$B$225)=LEFT($E$3,4)*1)*(납품대장!$G$2:$G$225>0),ROW(납품대장!$H$2:$H$225)-1),ROWS($B$9:B14))),"")} | C14: {=IFERROR(INDEX(납품대장!$D$2:$D$225,SMALL(IF((납품대장!$C$2:$C$225=$B$3)*(MONTH(납품대장!$B$2:$B$225)=MID($E$3,6,2)*1)*(YEAR(납품대장!$B$2:$B$225)=LEFT($E$3,4)*1)*(납품대장!$G$2:$G$225>0),ROW(납품대장!$D$2:$D$225)-1),ROWS($C$9:C14))),"")} | D14: {=IFERROR(INDEX(납품대장!$F$2:$F$225,SMALL(IF((납품대장!$C$2:$C$225=$B$3)*(MONTH(납품대장!$B$2:$B$225)=MID($E$3,6,2)*1)*(YEAR(납품대장!$B$2:$B$225)=LEFT($E$3,4)*1)*(납품대장!$G$2:$G$225>0),ROW(납품대장!$F$2:$F$225)-1),ROWS($D$9:D14))),"")} | E14: {=IFERROR(INDEX(납품대장!$E$2:$E$225,SMALL(IF((납품대장!$C$2:$C$225=$B$3)*(MONTH(납품대장!$B$2:$B$225)=MID($E$3,6,2)*1)*(YEAR(납품대장!$B$2:$B$225)=LEFT($E$3,4)*1)*(납품대장!$G$2:$G$225>0),ROW(납품대장!$E$2:$E$225)-1),ROWS($E$9:E14))),"")} | F14: {=IFERROR(INDEX(납품대장!$G$2:$G$225,SMALL(IF((납품대장!$C$2:$C$225=$B$3)*(MONTH(납품대장!$B$2:$B$225)=MID($E$3,6,2)*1)*(YEAR(납품대장!$B$2:$B$225)=LEFT($E$3,4)*1)*(납품대장!$G$2:$G$225>0),ROW(납품대장!$G$2:$G$225)-1),ROWS($F$9:F14))),"")}
A15: =IF(ROWS($A$9:A15)<=COUNTIFS(납품대장!$C:$C,$B$3,납품대장!$B:$B,">="&DATE(LEFT($E$3,4),MID($E$3,6,2),1),납품대장!$B:$B,"<"&DATE(LEFT($E$3,4),MID($E$3,6,2)+1,1),납품대장!$G:$G,">0"),ROWS($A$9:A15),"") | B15: {=IFERROR(INDEX(납품대장!$H$2:$H$225,SMALL(IF((납품대장!$C$2:$C$225=$B$3)*(MONTH(납품대장!$B$2:$B$225)=MID($E$3,6,2)*1)*(YEAR(납품대장!$B$2:$B$225)=LEFT($E$3,4)*1)*(납품대장!$G$2:$G$225>0),ROW(납품대장!$H$2:$H$225)-1),ROWS($B$9:B15))),"")} | C15: {=IFERROR(INDEX(납품대장!$D$2:$D$225,SMALL(IF((납품대장!$C$2:$C$225=$B$3)*(MONTH(납품대장!$B$2:$B$225)=MID($E$3,6,2)*1)*(YEAR(납품대장!$B$2:$B$225)=LEFT($E$3,4)*1)*(납품대장!$G$2:$G$225>0),ROW(납품대장!$D$2:$D$225)-1),ROWS($C$9:C15))),"")} | D15: {=IFERROR(INDEX(납품대장!$F$2:$F$225,SMALL(IF((납품대장!$C$2:$C$225=$B$3)*(MONTH(납품대장!$B$2:$B$225)=MID($E$3,6,2)*1)*(YEAR(납품대장!$B$2:$B$225)=LEFT($E$3,4)*1)*(납품대장!$G$2:$G$225>0),ROW(납품대장!$F$2:$F$225)-1),ROWS($D$9:D15))),"")} | E15: {=IFERROR(INDEX(납품대장!$E$2:$E$225,SMALL(IF((납품대장!$C$2:$C$225=$B$3)*(MONTH(납품대장!$B$2:$B$225)=MID($E$3,6,2)*1)*(YEAR(납품대장!$B$2:$B$225)=LEFT($E$3,4)*1)*(납품대장!$G$2:$G$225>0),ROW(납품대장!$E$2:$E$225)-1),ROWS($E$9:E15))),"")} | F15: {=IFERROR(INDEX(납품대장!$G$2:$G$225,SMALL(IF((납품대장!$C$2:$C$225=$B$3)*(MONTH(납품대장!$B$2:$B$225)=MID($E$3,6,2)*1)*(YEAR(납품대장!$B$2:$B$225)=LEFT($E$3,4)*1)*(납품대장!$G$2:$G$225>0),ROW(납품대장!$G$2:$G$225)-1),ROWS($F$9:F15))),"")}
A16: =IF(ROWS($A$9:A16)<=COUNTIFS(납품대장!$C:$C,$B$3,납품대장!$B:$B,">="&DATE(LEFT($E$3,4),MID($E$3,6,2),1),납품대장!$B:$B,"<"&DATE(LEFT($E$3,4),MID($E$3,6,2)+1,1),납품대장!$G:$G,">0"),ROWS($A$9:A16),"") | B16: {=IFERROR(INDEX(납품대장!$H$2:$H$225,SMALL(IF((납품대장!$C$2:$C$225=$B$3)*(MONTH(납품대장!$B$2:$B$225)=MID($E$3,6,2)*1)*(YEAR(납품대장!$B$2:$B$225)=LEFT($E$3,4)*1)*(납품대장!$G$2:$G$225>0),ROW(납품대장!$H$2:$H$225)-1),ROWS($B$9:B16))),"")} | C16: {=IFERROR(INDEX(납품대장!$D$2:$D$225,SMALL(IF((납품대장!$C$2:$C$225=$B$3)*(MONTH(납품대장!$B$2:$B$225)=MID($E$3,6,2)*1)*(YEAR(납품대장!$B$2:$B$225)=LEFT($E$3,4)*1)*(납품대장!$G$2:$G$225>0),ROW(납품대장!$D$2:$D$225)-1),ROWS($C$9:C16))),"")} | D16: {=IFERROR(INDEX(납품대장!$F$2:$F$225,SMALL(IF((납품대장!$C$2:$C$225=$B$3)*(MONTH(납품대장!$B$2:$B$225)=MID($E$3,6,2)*1)*(YEAR(납품대장!$B$2:$B$225)=LEFT($E$3,4)*1)*(납품대장!$G$2:$G$225>0),ROW(납품대장!$F$2:$F$225)-1),ROWS($D$9:D16))),"")} | E16: {=IFERROR(INDEX(납품대장!$E$2:$E$225,SMALL(IF((납품대장!$C$2:$C$225=$B$3)*(MONTH(납품대장!$B$2:$B$225)=MID($E$3,6,2)*1)*(YEAR(납품대장!$B$2:$B$225)=LEFT($E$3,4)*1)*(납품대장!$G$2:$G$225>0),ROW(납품대장!$E$2:$E$225)-1),ROWS($E$9:E16))),"")} | F16: {=IFERROR(INDEX(납품대장!$G$2:$G$225,SMALL(IF((납품대장!$C$2:$C$225=$B$3)*(MONTH(납품대장!$B$2:$B$225)=MID($E$3,6,2)*1)*(YEAR(납품대장!$B$2:$B$225)=LEFT($E$3,4)*1)*(납품대장!$G$2:$G$225>0),ROW(납품대장!$G$2:$G$225)-1),ROWS($F$9:F16))),"")}
A17: =IF(ROWS($A$9:A17)<=COUNTIFS(납품대장!$C:$C,$B$3,납품대장!$B:$B,">="&DATE(LEFT($E$3,4),MID($E$3,6,2),1),납품대장!$B:$B,"<"&DATE(LEFT($E$3,4),MID($E$3,6,2)+1,1),납품대장!$G:$G,">0"),ROWS($A$9:A17),"") | B17: {=IFERROR(INDEX(납품대장!$H$2:$H$225,SMALL(IF((납품대장!$C$2:$C$225=$B$3)*(MONTH(납품대장!$B$2:$B$225)=MID($E$3,6,2)*1)*(YEAR(납품대장!$B$2:$B$225)=LEFT($E$3,4)*1)*(납품대장!$G$2:$G$225>0),ROW(납품대장!$H$2:$H$225)-1),ROWS($B$9:B17))),"")} | C17: {=IFERROR(INDEX(납품대장!$D$2:$D$225,SMALL(IF((납품대장!$C$2:$C$225=$B$3)*(MONTH(납품대장!$B$2:$B$225)=MID($E$3,6,2)*1)*(YEAR(납품대장!$B$2:$B$225)=LEFT($E$3,4)*1)*(납품대장!$G$2:$G$225>0),ROW(납품대장!$D$2:$D$225)-1),ROWS($C$9:C17))),"")} | D17: {=IFERROR(INDEX(납품대장!$F$2:$F$225,SMALL(IF((납품대장!$C$2:$C$225=$B$3)*(MONTH(납품대장!$B$2:$B$225)=MID($E$3,6,2)*1)*(YEAR(납품대장!$B$2:$B$225)=LEFT($E$3,4)*1)*(납품대장!$G$2:$G$225>0),ROW(납품대장!$F$2:$F$225)-1),ROWS($D$9:D17))),"")} | E17: {=IFERROR(INDEX(납품대장!$E$2:$E$225,SMALL(IF((납품대장!$C$2:$C$225=$B$3)*(MONTH(납품대장!$B$2:$B$225)=MID($E$3,6,2)*1)*(YEAR(납품대장!$B$2:$B$225)=LEFT($E$3,4)*1)*(납품대장!$G$2:$G$225>0),ROW(납품대장!$E$2:$E$225)-1),ROWS($E$9:E17))),"")} | F17: {=IFERROR(INDEX(납품대장!$G$2:$G$225,SMALL(IF((납품대장!$C$2:$C$225=$B$3)*(MONTH(납품대장!$B$2:$B$225)=MID($E$3,6,2)*1)*(YEAR(납품대장!$B$2:$B$225)=LEFT($E$3,4)*1)*(납품대장!$G$2:$G$225>0),ROW(납품대장!$G$2:$G$225)-1),ROWS($F$9:F17))),"")}
A18: =IF(ROWS($A$9:A18)<=COUNTIFS(납품대장!$C:$C,$B$3,납품대장!$B:$B,">="&DATE(LEFT($E$3,4),MID($E$3,6,2),1),납품대장!$B:$B,"<"&DATE(LEFT($E$3,4),MID($E$3,6,2)+1,1),납품대장!$G:$G,">0"),ROWS($A$9:A18),"") | B18: {=IFERROR(INDEX(납품대장!$H$2:$H$225,SMALL(IF((납품대장!$C$2:$C$225=$B$3)*(MONTH(납품대장!$B$2:$B$225)=MID($E$3,6,2)*1)*(YEAR(납품대장!$B$2:$B$225)=LEFT($E$3,4)*1)*(납품대장!$G$2:$G$225>0),ROW(납품대장!$H$2:$H$225)-1),ROWS($B$9:B18))),"")} | C18: {=IFERROR(INDEX(납품대장!$D$2:$D$225,SMALL(IF((납품대장!$C$2:$C$225=$B$3)*(MONTH(납품대장!$B$2:$B$225)=MID($E$3,6,2)*1)*(YEAR(납품대장!$B$2:$B$225)=LEFT($E$3,4)*1)*(납품대장!$G$2:$G$225>0),ROW(납품대장!$D$2:$D$225)-1),ROWS($C$9:C18))),"")} | D18: {=IFERROR(INDEX(납품대장!$F$2:$F$225,SMALL(IF((납품대장!$C$2:$C$225=$B$3)*(MONTH(납품대장!$B$2:$B$225)=MID($E$3,6,2)*1)*(YEAR(납품대장!$B$2:$B$225)=LEFT($E$3,4)*1)*(납품대장!$G$2:$G$225>0),ROW(납품대장!$F$2:$F$225)-1),ROWS($D$9:D18))),"")} | E18: {=IFERROR(INDEX(납품대장!$E$2:$E$225,SMALL(IF((납품대장!$C$2:$C$225=$B$3)*(MONTH(납품대장!$B$2:$B$225)=MID($E$3,6,2)*1)*(YEAR(납품대장!$B$2:$B$225)=LEFT($E$3,4)*1)*(납품대장!$G$2:$G$225>0),ROW(납품대장!$E$2:$E$225)-1),ROWS($E$9:E18))),"")} | F18: {=IFERROR(INDEX(납품대장!$G$2:$G$225,SMALL(IF((납품대장!$C$2:$C$225=$B$3)*(MONTH(납품대장!$B$2:$B$225)=MID($E$3,6,2)*1)*(YEAR(납품대장!$B$2:$B$225)=LEFT($E$3,4)*1)*(납품대장!$G$2:$G$225>0),ROW(납품대장!$G$2:$G$225)-1),ROWS($F$9:F18))),"")}
A19: =IF(ROWS($A$9:A19)<=COUNTIFS(납품대장!$C:$C,$B$3,납품대장!$B:$B,">="&DATE(LEFT($E$3,4),MID($E$3,6,2),1),납품대장!$B:$B,"<"&DATE(LEFT($E$3,4),MID($E$3,6,2)+1,1),납품대장!$G:$G,">0"),ROWS($A$9:A19),"") | B19: {=IFERROR(INDEX(납품대장!$H$2:$H$225,SMALL(IF((납품대장!$C$2:$C$225=$B$3)*(MONTH(납품대장!$B$2:$B$225)=MID($E$3,6,2)*1)*(YEAR(납품대장!$B$2:$B$225)=LEFT($E$3,4)*1)*(납품대장!$G$2:$G$225>0),ROW(납품대장!$H$2:$H$225)-1),ROWS($B$9:B19))),"")} | C19: {=IFERROR(INDEX(납품대장!$D$2:$D$225,SMALL(IF((납품대장!$C$2:$C$225=$B$3)*(MONTH(납품대장!$B$2:$B$225)=MID($E$3,6,2)*1)*(YEAR(납품대장!$B$2:$B$225)=LEFT($E$3,4)*1)*(납품대장!$G$2:$G$225>0),ROW(납품대장!$D$2:$D$225)-1),ROWS($C$9:C19))),"")} | D19: {=IFERROR(INDEX(납품대장!$F$2:$F$225,SMALL(IF((납품대장!$C$2:$C$225=$B$3)*(MONTH(납품대장!$B$2:$B$225)=MID($E$3,6,2)*1)*(YEAR(납품대장!$B$2:$B$225)=LEFT($E$3,4)*1)*(납품대장!$G$2:$G$225>0),ROW(납품대장!$F$2:$F$225)-1),ROWS($D$9:D19))),"")} | E19: {=IFERROR(INDEX(납품대장!$E$2:$E$225,SMALL(IF((납품대장!$C$2:$C$225=$B$3)*(MONTH(납품대장!$B$2:$B$225)=MID($E$3,6,2)*1)*(YEAR(납품대장!$B$2:$B$225)=LEFT($E$3,4)*1)*(납품대장!$G$2:$G$225>0),ROW(납품대장!$E$2:$E$225)-1),ROWS($E$9:E19))),"")} | F19: {=IFERROR(INDEX(납품대장!$G$2:$G$225,SMALL(IF((납품대장!$C$2:$C$225=$B$3)*(MONTH(납품대장!$B$2:$B$225)=MID($E$3,6,2)*1)*(YEAR(납품대장!$B$2:$B$225)=LEFT($E$3,4)*1)*(납품대장!$G$2:$G$225>0),ROW(납품대장!$G$2:$G$225)-1),ROWS($F$9:F19))),"")}
A20: =IF(ROWS($A$9:A20)<=COUNTIFS(납품대장!$C:$C,$B$3,납품대장!$B:$B,">="&DATE(LEFT($E$3,4),MID($E$3,6,2),1),납품대장!$B:$B,"<"&DATE(LEFT($E$3,4),MID($E$3,6,2)+1,1),납품대장!$G:$G,">0"),ROWS($A$9:A20),"") | B20: {=IFERROR(INDEX(납품대장!$H$2:$H$225,SMALL(IF((납품대장!$C$2:$C$225=$B$3)*(MONTH(납품대장!$B$2:$B$225)=MID($E$3,6,2)*1)*(YEAR(납품대장!$B$2:$B$225)=LEFT($E$3,4)*1)*(납품대장!$G$2:$G$225>0),ROW(납품대장!$H$2:$H$225)-1),ROWS($B$9:B20))),"")} | C20: {=IFERROR(INDEX(납품대장!$D$2:$D$225,SMALL(IF((납품대장!$C$2:$C$225=$B$3)*(MONTH(납품대장!$B$2:$B$225)=MID($E$3,6,2)*1)*(YEAR(납품대장!$B$2:$B$225)=LEFT($E$3,4)*1)*(납품대장!$G$2:$G$225>0),ROW(납품대장!$D$2:$D$225)-1),ROWS($C$9:C20))),"")} | D20: {=IFERROR(INDEX(납품대장!$F$2:$F$225,SMALL(IF((납품대장!$C$2:$C$225=$B$3)*(MONTH(납품대장!$B$2:$B$225)=MID($E$3,6,2)*1)*(YEAR(납품대장!$B$2:$B$225)=LEFT($E$3,4)*1)*(납품대장!$G$2:$G$225>0),ROW(납품대장!$F$2:$F$225)-1),ROWS($D$9:D20))),"")} | E20: {=IFERROR(INDEX(납품대장!$E$2:$E$225,SMALL(IF((납품대장!$C$2:$C$225=$B$3)*(MONTH(납품대장!$B$2:$B$225)=MID($E$3,6,2)*1)*(YEAR(납품대장!$B$2:$B$225)=LEFT($E$3,4)*1)*(납품대장!$G$2:$G$225>0),ROW(납품대장!$E$2:$E$225)-1),ROWS($E$9:E20))),"")} | F20: {=IFERROR(INDEX(납품대장!$G$2:$G$225,SMALL(IF((납품대장!$C$2:$C$225=$B$3)*(MONTH(납품대장!$B$2:$B$225)=MID($E$3,6,2)*1)*(YEAR(납품대장!$B$2:$B$225)=LEFT($E$3,4)*1)*(납품대장!$G$2:$G$225>0),ROW(납품대장!$G$2:$G$225)-1),ROWS($F$9:F20))),"")}
... A28: =IF(ROWS($A$9:A28)<=COUNTIFS(납품대장!$C:$C,$B$3,납품대장!$B:$B,">="&DATE(LEFT($E$3,4),MID($E$3,6,2),1),납품대장!$B:$B,"<"&DATE(LEFT($E$3,4),MID($E$3,6,2)+1,1),납품대장!$G:$G,">0"),ROWS($A$9:A28),"") | B28: {=IFERROR(INDEX(납품대장!$H$2:$H$225,SMALL(IF((납품대장!$C$2:$C$225=$B$3)*(MONTH(납품대장!$B$2:$B$225)=MID($E$3,6,2)*1)*(YEAR(납품대장!$B$2:$B$225)=LEFT($E$3,4)*1)*(납품대장!$G$2:$G$225>0),ROW(납품대장!$H$2:$H$225)-1),ROWS($B$9:B28))),"")} | C28: {=IFERROR(INDEX(납품대장!$D$2:$D$225,SMALL(IF((납품대장!$C$2:$C$225=$B$3)*(MONTH(납품대장!$B$2:$B$225)=MID($E$3,6,2)*1)*(YEAR(납품대장!$B$2:$B$225)=LEFT($E$3,4)*1)*(납품대장!$G$2:$G$225>0),ROW(납품대장!$D$2:$D$225)-1),ROWS($C$9:C28))),"")} | D28: {=IFERROR(INDEX(납품대장!$F$2:$F$225,SMALL(IF((납품대장!$C$2:$C$225=$B$3)*(MONTH(납품대장!$B$2:$B$225)=MID($E$3,6,2)*1)*(YEAR(납품대장!$B$2:$B$225)=LEFT($E$3,4)*1)*(납품대장!$G$2:$G$225>0),ROW(납품대장!$F$2:$F$225)-1),ROWS($D$9:D28))),"")} | E28: {=IFERROR(INDEX(납품대장!$E$2:$E$225,SMALL(IF((납품대장!$C$2:$C$225=$B$3)*(MONTH(납품대장!$B$2:$B$225)=MID($E$3,6,2)*1)*(YEAR(납품대장!$B$2:$B$225)=LEFT($E$3,4)*1)*(납품대장!$G$2:$G$225>0),ROW(납품대장!$E$2:$E$225)-1),ROWS($E$9:E28))),"")} | F28: {=IFERROR(INDEX(납품대장!$G$2:$G$225,SMALL(IF((납품대장!$C$2:$C$225=$B$3)*(MONTH(납품대장!$B$2:$B$225)=MID($E$3,6,2)*1)*(YEAR(납품대장!$B$2:$B$225)=LEFT($E$3,4)*1)*(납품대장!$G$2:$G$225>0),ROW(납품대장!$G$2:$G$225)-1),ROWS($F$9:F28))),"")}
A30: 합계
D32: 담당 | E32: 검토 | F32: 승인

Sheet 납품대장
A1: 연번 | B1: 주문일자 | C1: 매장명 | D1: 작물명 | E1: 단가 | F1: 주문수량(g) | G1: 금액 | H1: 납품일자 | I1: 비고 | K1: 작물명 | L1: 단가(1g)
A2: =IF(B2<>"",ROW()-1,"") | B2: 45902 | C2: 419국수김밥 | D2: 루꼴라 | E2: =VLOOKUP(표1[[#This Row],[작물명]],$K$2:$L$5,2,FALSE) | F2: 500 | G2: =F2*$L$2 | H2: 45904 | K2: 루꼴라 | L2: 17.7
A3: =IF(B3<>"",ROW()-1,"") | B3: 45904 | C3: 까미노 | D3: 루꼴라 | E3: =VLOOKUP(표1[[#This Row],[작물명]],$K$2:$L$5,2,FALSE) | F3: 1000 | G3: =F3*$L$2 | H3: 45904 | K3: 엽채류 | L3: 11.5
A4: =IF(B4<>"",ROW()-1,"") | B4: 45904 | C4: 미즐 카페엠 | D4: 루꼴라 | E4: =VLOOKUP(표1[[#This Row],[작물명]],$K$2:$L$5,2,FALSE) | F4: 100 | G4: =F4*$L$2 | H4: 45904 | K4: 애플민트 | L4: 56.6
A5: =IF(B5<>"",ROW()-1,"") | B5: 45909 | C5: 봄타코 | D5: 루꼴라 | E5: =VLOOKUP(표1[[#This Row],[작물명]],$K$2:$L$5,2,FALSE) | F5: 800 | G5: =F5*$L$2 | H5: 45911 | K5: 바질 | L5: 30
A6: =IF(B6<>"",ROW()-1,"") | B6: 45909 | C6: 봄타코 | D6: 루꼴라 | E6: =VLOOKUP(표1[[#This Row],[작물명]],$K$2:$L$5,2,FALSE) | F6: 200 | G6: 0 | H6: 45911 | I6: 시식용 | K6: 딸기(설향) | L6: 10
A7: =IF(B7<>"",ROW()-1,"") | B7: 45909 | C7: 남해횟집 | D7: 루꼴라 | E7: =VLOOKUP(표1[[#This Row],[작물명]],$K$2:$L$5,2,FALSE) | F7: 400 | G7: 0 | H7: 45911 | I7: 테스트용 | K7: 애플수박 | L7: 8
A8: =IF(B8<>"",ROW()-1,"") | B8: 45909 | C8: 까미노 | D8: 루꼴라 | E8: =VLOOKUP(표1[[#This Row],[작물명]],$K$2:$L$5,2,FALSE) | F8: 300 | G8: 0 | H8: 45911 | I8: 시식용
A9: =IF(B9<>"",ROW()-1,"") | B9: 45909 | C9: 요요네 | D9: 루꼴라 | E9: =VLOOKUP(표1[[#This Row],[작물명]],$K$2:$L$5,2,FALSE) | F9: 400 | G9: =F9*$L$2 | H9: 45911
A10: =IF(B10<>"",ROW()-1,"") | B10: 45909 | C10: 까미노 | D10: 루꼴라 | E10: =VLOOKUP(표1[[#This Row],[작물명]],$K$2:$L$5,2,FALSE) | F10: 500 | G10: =F10*$L$2 | H10: 45911
A11: =IF(B11<>"",ROW()-1,"") | B11: 45909 | C11: 419국수김밥 | D11: 루꼴라 | E11: =VLOOKUP(표1[[#This Row],[작물명]],$K$2:$L$5,2,FALSE) | F11: 500 | G11: =F11*$L$2 | H11: 45911
A12: =IF(B12<>"",ROW()-1,"") | B12: 45910 | C12: 크을농 | D12: 루꼴라 | E12: =VLOOKUP(표1[[#This Row],[작물명]],$K$2:$L$5,2,FALSE) | F12: 500 | G12: 0 | H12: 45911 | I12: 시식용
A13: =IF(B13<>"",ROW()-1,"") | B13: 45910 | C13: 미즐 카페엠 | D13: 루꼴라 | E13: =VLOOKUP(표1[[#This Row],[작물명]],$K$2:$L$5,2,FALSE) | F13: 100 | G13: 0 | H13: 45911 | I13: 시식용
A14: =IF(B14<>"",ROW()-1,"") | B14: 45910 | C14: 미즐 카페엠 | D14: 루꼴라 | E14: =VLOOKUP(표1[[#This Row],[작물명]],$K$2:$L$5,2,FALSE) | F14: 100 | G14: =F14*$L$2 | H14: 45911
A15: =IF(B15<>"",ROW()-1,"") | B15: 45910 | C15: 미즐 카페엠 | D15: 엽채류 | E15: =VLOOKUP(표1[[#This Row],[작물명]],$K$2:$L$5,2,FALSE) | G15: =F15*$L$2 | H15: 45911 | I15: 종류별
A16: =IF(B16<>"",ROW()-1,"") | B16: 45910 | C16: 요요네 | D16: 루꼴라 | E16: =VLOOKUP(표1[[#This Row],[작물명]],$K$2:$L$5,2,FALSE) | F16: 300 | G16: 0 | H16: 45911 | I16: 시식용
A17: =IF(B17<>"",ROW()-1,"") | B17: 45915 | C17: 까미노 | D17: 루꼴라 | E17: =VLOOKUP(표1[[#This Row],[작물명]],$K$2:$L$5,2,FALSE) | F17: 500 | G17: =F17*$L$2 | H17: 45916
A18: =IF(B18<>"",ROW()-1,"") | B18: 45915 | C18: 미즐 카페엠 | D18: 루꼴라 | E18: =VLOOKUP(표1[[#This Row],[작물명]],$K$2:$L$5,2,FALSE) | F18: 300 | G18: =F18*$L$2 | H18: 45919 | I18: 금요일 납품
A19: =IF(B19<>"",ROW()-1,"") | B19: 45915 | C19: 미즐 카페엠 | D19: 엽채류 | E19: =VLOOKUP(표1[[#This Row],[작물명]],$K$2:$L$5,2,FALSE) | F19: 300 | G19: =F19*11.5 | H19: 45919 | I19: 금요일 납품
A20: =IF(B20<>"",ROW()-1,"") | B20: 45918 | C20: 봄타코 | D20: 루꼴라 | E20: =VLOOKUP(표1[[#This Row],[작물명]],$K$2:$L$5,2,FALSE) | F20: 500 | G20: =F20*$L$2 | H20: 45919
A21: =IF(B21<>"",ROW()-1,"") | B21: 45918 | C21: 까미노 | D21: 루꼴라 | E21: =VLOOKUP(표1[[#This Row],[작물명]],$K$2:$L$5,2,FALSE) | F21: 1000 | G21: =F21*$L$2 | H21: 45919
A22: =IF(B22<>"",ROW()-1,"") | B22: 45918 | C22: 419국수김밥 | D22: 루꼴라 | E22: =VLOOKUP(표1[[#This Row],[작물명]],$K$2:$L$5,2,FALSE) | F22: 500 | G22: =F22*$L$2 | H22: 45919
A23: =IF(B23<>"",ROW()-1,"") | B23: 45918 | C23: 419국수김밥 | E23: =VLOOKUP(표1[[#This Row],[작물명]],$K$2:$L$5,2,FALSE) | G23: -10000 | I23: 기자 인터뷰 시식(김밥 2줄)
A24: =IF(B24<>"",ROW()-1,"") | B24: 45918 | C24: 까미노 | E24: =VLOOKUP(표1[[#This Row],[작물명]],$K$2:$L$5,2,FALSE) | G24: -11000 | I24: 기자 인터뷰 시식(빵 2개)
A25: =IF(B25<>"",ROW()-1,"") | B25: 45918 | C25: 봄타코 | E25: =VLOOKUP(표1[[#This Row],[작물명]],$K$2:$L$5,2,FALSE) | G25: -11000 | I25: 기자 인터뷰 시식(타코 1개)
A26: =IF(B26<>"",ROW()-1,"") | B26: 45918 | C26: 요요네 | E26: =VLOOKUP(표1[[#This Row],[작물명]],$K$2:$L$5,2,FALSE) | G26: -19000 | I26: 기자 인터뷰 시식(메뉴 2개)
A27: =IF(B27<>"",ROW()-1,"") | B27: 45922 | C27: 까미노 | D27: 루꼴라 | E27: =VLOOKUP(표1[[#This Row],[작물명]],$K$2:$L$5,2,FALSE) | F27: 500 | G27: =F27*$L$2 | H27: 45923
A28: =IF(B28<>"",ROW()-1,"") | B28: 45925 | C28: 까미노 | D28: 루꼴라 | E28: =VLOOKUP(표1[[#This Row],[작물명]],$K$2:$L$5,2,FALSE) | F28: 700 | G28: =F28*$L$2 | H28: 45926
A29: =IF(B29<>"",ROW()-1,"") | B29: 45925 | C29: 봄타코 | D29: 루꼴라 | E29: =VLOOKUP(표1[[#This Row],[작물명]],$K$2:$L$5,2,FALSE) | F29: 500 | G29: =F29*$L$2 | H29: 45926
A30: =IF(B30<>"",ROW()-1,"") | B30: 45929 | C30: 미즐 카페엠 | D30: 엽채류 | E30: =VLOOKUP(표1[[#This Row],[작물명]],$K$2:$L$5,2,FALSE) | F30: 300 | G30: =IF(표1[[#This Row],[작물명]]=K2,표1[[#This Row],[주문수량(g)]]*L2,표1[[#This Row],[주문수량(g)]]*L3) | H30: 45930
A31: =IF(B31<>"",ROW()-1,"") | B31: 45929 | C31: 까미노 | D31: 루꼴라 | E31: =VLOOKUP(표1[[#This Row],[작물명]],$K$2:$L$5,2,FALSE) | F31: 2000 | G31: =F31*$L$2 | H31: 45930
A32: =IF(B32<>"",ROW()-1,"") | B32: 45929 | C32: 화수브루어리 | D32: 루꼴라 | E32: =VLOOKUP(표1[[#This Row],[작물명]],$K$2:$L$5,2,FALSE) | F32: 500 | G32: =F32*$L$2 | H32: 45930
A33: =IF(B33<>"",ROW()-1,"") | B33: 45931 | C33: 봄타코 | D33: 루꼴라 | E33: =VLOOKUP(표1[[#This Row],[작물명]],$K$2:$L$5,2,FALSE) | F33: 600 | G33: =F33*$L$2 | H33: 45932
A34: =IF(B34<>"",ROW()-1,"") | B34: 45940 | C34: 까미노 | D34: 루꼴라 | E34: =VLOOKUP(표1[[#This Row],[작물명]],$K$2:$L$5,2,FALSE) | F34: 1000 | G34: =F34*$L$2 | H34: 45940
A35: =IF(B35<>"",ROW()-1,"") | B35: 45940 | C35: 재간정 | D35: 애플민트 | E35: =VLOOKUP(표1[[#This Row],[작물명]],$K$2:$L$5,2,FALSE) | F35: 300 | G35: =F35*$L$2 | H35: 45940
A36: =IF(B36<>"",ROW()-1,"") | B36: 45943 | C36: 419국수김밥 | D36: 루꼴라 | E36: =VLOOKUP(표1[[#This Row],[작물명]],$K$2:$L$5,2,FALSE) | F36: 5000 | G36: =F36*$L$2 | H36: 45944
A37: =IF(B37<>"",ROW()-1,"") | B37: 45943 | C37: 화수브루어리 | D37: 루꼴라 | E37: =VLOOKUP(표1[[#This Row],[작물명]],$K$2:$L$5,2,FALSE) | F37: 500 | G37: =F37*$L$2 | H37: 45944
A38: =IF(B38<>"",ROW()-1,"") | B38: 45945 | C38: 미즐 카페엠 | D38: 루꼴라 | E38: =VLOOKUP(표1[[#This Row],[작물명]],$K$2:$L$5,2,FALSE) | F38: 200 | G38: =표1[[#This Row],[단가]]*표1[[#This Row],[주문수량(g)]] | H38: 45946
A39: =IF(B39<>"",ROW()-1,"") | B39: 45945 | C39: 미즐 카페엠 | D39: 엽채류 | E39: =VLOOKUP(표1[[#This Row],[작물명]],$K$2:$L$5,2,FALSE) | F39: 200 | G39: =표1[[#This Row],[단가]]*표1[[#This Row],[주문수량(g)]] | H39: 45946 | I39: 이자트릭스
A40: =IF(B40<>"",ROW()-1,"") | B40: 45945 | C40: 까미노 | D40: 루꼴라 | E40: =VLOOKUP(표1[[#This Row],[작물명]],$K$2:$L$5,2,FALSE) | F40: 2000 | G40: =표1[[#This Row],[단가]]*표1[[#This Row],[주문수량(g)]] | H40: 45946 | I40: 300g씩 소분 요청
...

Sheet 납품확인서
B1: 납품확인서
H2: 222
A3: 납품일자 | C3: =VLOOKUP(H2,납품대장!$A$2:$G$225,2,FALSE)
A4: 물 품 명 | C4: =IFERROR(VLOOKUP(H2,납품대장!$A$2:$I$225,4,FALSE),"") & IFERROR(IF(VLOOKUP(H2,납품대장!$A$2:$I$225,9,FALSE)="","", "(" & VLOOKUP(H2,납품대장!$A$2:$I$225,9,FALSE) & ")"),"")
A5: 납품수량 | C5: =VLOOKUP(H2,납품대장!$A$2:$G$225,6,FALSE)&"g"
A6: 금 액 | C6: =VLOOKUP(H2,납품대장!$A$2:$G$225,7,FALSE)
A7: 위와 같이 정히 수령하였음을 확인함.
F8: 업소명 | G8: =VLOOKUP(H2,납품대장!$A$2:$G$225,3,FALSE)
F9: 확인자 | H9: 박 기 남 (인)
B12: 납품확인서
H13: =H2
A14: 납품일자 | C14: =+C3
A15: 물 품 명 | C15: =IFERROR(VLOOKUP(H2,납품대장!$A$2:$I$225,4,FALSE),"") & IFERROR(IF(VLOOKUP(H2,납품대장!$A$2:$I$225,9,FALSE)="","", "(" & VLOOKUP(H2,납품대장!$A$2:$I$225,9,FALSE) & ")"),"")
A16: 납품수량 | C16: =VLOOKUP(H13,납품대장!$A$2:$G$225,6,FALSE)&"g"
A17: 금 액 | C17: =VLOOKUP(H2,납품대장!$A$2:$G$225,7,FALSE)
A18: 위와 같이 정히 수령하였음을 확인함.
F19: 업소명 | G19: =VLOOKUP(H2,납품대장!$A$2:$G$225,3,FALSE)
F20: 확인자 | H20: (인)

Sheet 협력매장 목록
A1: 업소명 | B1: 주소 | C1: 메뉴 | D1: 가격 | E1: 메뉴 | F1: 가격
A2: 419국수김밥 | B2: 강북구 4.19로 31 | C2: 루꼴라 크림치즈김밥 | D2: 5000
A3: 요요네 | B3: 강북구 4.19로 16 | C3: 루꼴라 반산스 | D3: 9000 | E3: 루꼴라 감자뢰스티 | F3: 100000
A4: 까미노 | B4: 강북구 4.19로 61 | C4: 루꼴라 피자빵 | D4: 5500
A5: 미즐 카페엠 | B5: 강북구 4.19로 107 | C5: 루꼴라 로스트 치킨샐러드 | D5: 24000 | E5: 루꼴라 부라타치즈 샐러드 | F5: 22000
A6: 봄타코 | B6: 강북구 4.19로 60 | C6: 루꼴라 살시치아 타코 | D6: 11000
A7: 크을농 | B7: 강북구 4.19로 91 | C7: 루꼴라 들기름 두부전 | D7: 15000
A8: 남해횟집 | B8: 강북구 4.19로 40
A9: 이설함흥냉면 | B9: 강북구 4.19로 42
A10: 화수브루어리 | B10: 강북구 인수봉로 238
A11: 재간정 | B11: 강북구 도봉로101길 18
A12: 민지네 | B12: 강북구 한천로139가길 18 1층
A13: 온터 | B13: 강북구 인수봉로 310 1층
A14: 비르케 | B14: 강북구 4.19로 43

Sheet 9월 결제
A1: 연번 | B1: 주문일자 | C1: 매장명 | D1: 작물명 | E1: 단가(g) | F1: 주문수량(g) | G1: 금액 | H1: 납품일자 | I1: 비고 | K1: 연번 | L1: 주문일자 | M1: 매장명 | N1: 작물명 | O1: 단가(g) | P1: 주문수량(g) | Q1: 금액 | R1: 납품일자 | S1: 비고
A2: 1 | B2: 45902 | C2: 419국수김밥 | D2: 루꼴라 | E2: 17.7 | F2: 500 | G2: 8850 | H2: 45904 | K2: 4 | L2: 45909 | M2: 봄타코 | N2: 루꼴라 | O2: 17.7 | P2: 800 | Q2: 14160 | R2: 45911
A3: 2 | B3: 45909 | C3: 419국수김밥 | D3: 루꼴라 | E3: 17.7 | F3: 500 | G3: 8850 | H3: 45911 | K3: 5 | L3: 45909 | M3: 봄타코 | N3: 루꼴라 | O3: 17.7 | P3: 200 | Q3: 0 | R3: 45911 | S3: 시식용
A4: 3 | B4: 45918 | C4: 419국수김밥 | D4: 루꼴라 | E4: 17.7 | F4: 500 | G4: 8850 | H4: 45919 | K4: 19 | L4: 45918 | M4: 봄타코 | N4: 루꼴라 | O4: 17.7 | P4: 500 | Q4: 8850 | R4: 45919
A5: 4 | B5: 45918 | C5: 419국수김밥 | G5: -10000 | I5: 기자 인터뷰 시식(김밥 2줄) | K5: 24 | L5: 45918 | M5: 봄타코 | Q5: -11000 | S5: 기자 인터뷰 시식(타코 1개)
A6: 계 | G6: =SUM(G2:G5)-G5 | K6: 28 | L6: 45925 | M6: 봄타코 | N6: 루꼴라 | O6: 17.7 | P6: 500 | Q6: 8850 | R6: 45926
K7: 계 | Q7: =SUM(Q2:Q6)-Q5
A9: 연번 | B9: 주문일자 | C9: 매장명 | D9: 작물명 | E9: 단가(g) | F9: 주문수량(g) | G9: 금액 | H9: 납품일자 | I9: 비고 | K9: 연번 | L9: 주문일자 | M9: 매장명 | N9: 작물명 | O9: 단가(g) | P9: 주문수량(g) | Q9: 금액 | R9: 납품일자 | S9: 비고
A10: 1 | B10: 45904 | C10: 까미노 | D10: 루꼴라 | E10: 17.7 | F10: 1000 | G10: 17700 | H10: 45904 | K10: 1 | L10: 45929 | M10: 화수브루어리 | N10: 루꼴라 | O10: 17.7 | P10: 500 | Q10: 8850 | R10: 45930
A11: 2 | B11: 45909 | C11: 까미노 | D11: 루꼴라 | E11: 17.7 | F11: 300 | G11: 0 | H11: 45911 | I11: 시식용 | K11: 계 | Q11: =SUM(Q10)
A12: 3 | B12: 45909 | C12: 까미노 | D12: 루꼴라 | E12: 17.7 | F12: 500 | G12: 8850 | H12: 45911
A13: 4 | B13: 45915 | C13: 까미노 | D13: 루꼴라 | E13: 17.7 | F13: 500 | G13: 8850 | H13: 45916
A14: 5 | B14: 45918 | C14: 까미노 | D14: 루꼴라 | E14: 17.7 | F14: 1000 | G14: 17700 | H14: 45919
A15: 6 | B15: 45918 | C15: 까미노 | G15: -11000 | I15: 기자 인터뷰 시식(빵 2개)
A16: 7 | B16: 45922 | C16: 까미노 | D16: 루꼴라 | E16: 17.7 | F16: 500 | G16: 8850 | H16: 45923
A17: 8 | B17: 45925 | C17: 까미노 | D17: 루꼴라 | E17: 17.7 | F17: 700 | G17: 12390 | H17: 45926
A18: 9 | B18: 45929 | C18: 까미노 | D18: 루꼴라 | E18: 17.7 | F18: 2000 | G18: 35400 | H18: 45930
A19: 계 | G19: =SUM(G10:G18)-G15
A22: 연번 | B22: 주문일자 | C22: 매장명 | D22: 작물명 | E22: 단가(g) | F22: 주문수량(g) | G22: 금액 | H22: 납품일자 | I22: 비고
A23: 1 | B23: 45904 | C23: 미즐 카페엠 | D23: 루꼴라 | E23: 17.7 | F23: 100 | G23: 1770 | H23: 45904
A24: 2 | B24: 45910 | C24: 미즐 카페엠 | D24: 루꼴라 | F24: 100 | G24: 0 | H24: 45911 | I24: 시식용
A25: 3 | B25: 45910 | C25: 미즐 카페엠 | D25: 루꼴라 | E25: 17.7 | F25: 100 | G25: 1770 | H25: 45911
A26: 4 | B26: 45910 | C26: 미즐 카페엠 | D26: 엽채류 | G26: 0 | H26: 45911 | I26: 종류별
A27: 5 | B27: 45915 | C27: 미즐 카페엠 | D27: 루꼴라 | E27: 17.7 | F27: 300 | G27: 5310 | H27: 45919 | I27: 금요일 납품
A28: 6 | B28: 45915 | C28: 미즐 카페엠 | D28: 엽채류 | E28: 17.7 | F28: 300 | G28: 3450 | H28: 45919 | I28: 금요일 납품
A29: 7 | B29: 45929 | C29: 미즐 카페엠 | D29: 엽채류 | E29: 17.7 | F29: 300 | G29: 3450 | H29: 45930
A30: 계 | G30: =SUM(G23:G29)

Sheet 10월 결제
A1: 주문일자 | B1: 매장명 | C1: 작물명 | D1: 단가 | E1: 주문수량(g) | F1: 금액 | G1: 납품일자 | H1: 비고 | J1: 주문일자 | K1: 매장명 | L1: 작물명 | M1: 단가 | N1: 주문수량(g) | O1: 금액 | P1: 납품일자 | Q1: 비고
A2: 45909 | B2: 봄타코 | C2: 루꼴라 | D2: 17.7 | E2: 800 | F2: 14160 | G2: 45911 | J2: 45945 | K2: 미즐 카페엠 | L2: 루꼴라 | M2: 17.7 | N2: 200 | O2: 3540
A3: 45909 | B3: 봄타코 | C3: 루꼴라 | D3: 17.7 | E3: 200 | F3: 0 | G3: 45911 | H3: 시식용 | J3: 45945 | K3: 미즐 카페엠 | L3: 엽채류 | M3: 11.5 | N3: 200 | O3: 2300 | Q3: 이자트릭스
A4: 45918 | B4: 봄타코 | C4: 루꼴라 | D4: 17.7 | E4: 500 | F4: 8850 | G4: 45919 | J4: 45954 | K4: 미즐 카페엠 | L4: 루꼴라 | M4: 17.7 | N4: 300 | O4: 5310
A5: 45918 | B5: 봄타코 | F5: -11000 | H5: 기자 인터뷰 시식(타코 1개) | J5: 45954 | K5: 미즐 카페엠 | L5: 엽채류 | M5: 11.5 | N5: 300 | O5: 3450 | Q5: 이자트릭스
A6: 45925 | B6: 봄타코 | C6: 루꼴라 | D6: 17.7 | E6: 500 | F6: 8850 | G6: 45926 | J6: 계 | O6: =SUM(O2:O5)
A7: 45931 | B7: 봄타코 | C7: 루꼴라 | D7: 17.7 | E7: 600 | F7: 10620 | G7: 45932
A8: 계 | F8: =SUM(F2:F7)-F5
A11: 주문일자 | B11: 매장명 | C11: 작물명 | D11: 단가 | E11: 주문수량(g) | F11: 금액 | G11: 납품일자 | H11: 비고 | J11: 주문일자 | K11: 매장명 | L11: 작물명 | M11: 단가 | N11: 주문수량(g) | O11: 금액 | P11: 납품일자 | Q11: 비고
A12: 45943 | B12: 419국수김밥 | C12: 루꼴라 | D12: 17.7 | E12: 5000 | F12: 88500 | G12: 45944 | J12: 45945 | K12: 크을농 | L12: 루꼴라 | M12: 17.7 | N12: 4000 | O12: 70800
A13: 45951 | B13: 419국수김밥 | C13: 루꼴라 | D13: 17.7 | E13: 1000 | F13: 17700 | J13: 45960 | K13: 크을농 | L13: 루꼴라 | M13: 17.7 | N13: 200 | O13: 3540
A14: 계 | F14: =SUM(F12:F13) | J14: 계 | O14: =SUM(O12:O13)
A17: 주문일자 | B17: 매장명 | C17: 작물명 | D17: 단가 | E17: 주문수량(g) | F17: 금액 | G17: 납품일자 | H17: 비고
A18: 45940 | B18: 까미노 | C18: 루꼴라 | D18: 17.7 | E18: 1000 | F18: 17700 | G18: 45940 | J18: 주문일자 | K18: 매장명 | L18: 작물명 | M18: 단가 | N18: 주문수량(g) | O18: 금액 | P18: 납품일자 | Q18: 비고
A19: 45945 | B19: 까미노 | C19: 루꼴라 | D19: 17.7 | E19: 2000 | F19: 35400 | H19: 300g씩 소분 요청 | J19: 45943 | K19: 화수브루어리 | L19: 루꼴라 | M19: 17.7 | N19: 500 | O19: 8850
A20: 45950 | B20: 까미노 | C20: 루꼴라 | D20: 17.7 | E20: 1000 | F20: 17700 | H20: 300g씩 소분 요청
A21: 45954 | B21: 까미노 | C21: 루꼴라 | D21: 17.7 | E21: 1500 | F21: 26550
A22: 계 | F22: =SUM(F18:F21)
